<?xml version="1.0" ?>
<!-- =================================================================================== -->
<!-- |    This document was autogenerated by xacro from mbot.xacro                     | -->
<!-- |    EDITING THIS FILE BY HAND IS NOT RECOMMENDED                                 | -->
<!-- =================================================================================== -->
<robot name="mbot">
  <!-- Defining the colors used in this robot -->
  <material name="yellow">
    <color rgba="1 0.4 0 1"/>
  </material>
  <material name="black">
    <color rgba="0 0 0 0.95"/>
  </material>
  <material name="gray">
    <color rgba="0.75 0.75 0.75 1"/>
  </material>
  <link name="base_footprint">
    <visual>
      <origin rpy="0 0 0" xyz="0 0 0"/>
      <geometry>
        <box size="0.001 0.001 0.001"/>
      </geometry>
    </visual>
  </link>
  <joint name="base_footprint_joint" type="fixed">
    <origin rpy="0 0 0" xyz="0 0 0.5249999999999999"/>
    <parent link="base_footprint"/>
    <child link="base_link"/>
  </joint>
  <link name="base_link">
    <visual>
      <origin rpy="0 0 0" xyz=" 0 0 0"/>
      <geometry>
        <box size="4.43 1.74 0.7"/>
      </geometry>
      <material name="yellow"/>
    </visual>
  </link>
  <joint name="base_l_wheel_joint" type="continuous">
    <origin rpy="0 0 0" xyz="1.2 -0.87 -0.17"/>
    <parent link="base_link"/>
    <child link="base_l_wheel_link"/>
    <axis xyz="0 1 0"/>
  </joint>
  <link name="base_l_wheel_link">
    <visual>
      <origin rpy="1.5707963 0 0" xyz="0 0 0"/>
      <geometry>
        <cylinder length="0.11" radius="0.35"/>
      </geometry>
      <material name="gray"/>
    </visual>
  </link>
  <joint name="base_r_wheel_joint" type="continuous">
    <origin rpy="0 0 0" xyz="1.2 0.87 -0.17"/>
    <parent link="base_link"/>
    <child link="base_r_wheel_link"/>
    <axis xyz="0 1 0"/>
  </joint>
  <link name="base_r_wheel_link">
    <visual>
      <origin rpy="1.5707963 0 0" xyz="0 0 0"/>
      <geometry>
        <cylinder length="0.11" radius="0.35"/>
      </geometry>
      <material name="gray"/>
    </visual>
  </link>
  <joint name="left_caster_joint" type="continuous">
    <origin rpy="0 0 0" xyz="-1.2 0.87 -0.17"/>
    <parent link="base_link"/>
    <child link="left_caster_link"/>
    <axis xyz="0 1 0"/>
  </joint>
  <link name="left_caster_link">
    <visual>
      <origin rpy="1.5707963 0 0" xyz="0 0 0"/>
      <geometry>
        <cylinder length="0.11" radius="0.35"/>
      </geometry>
      <material name="black"/>
    </visual>
  </link>
  <joint name="right_caster_joint" type="continuous">
    <origin rpy="0 0 0" xyz="-1.2 -0.87 -0.17"/>
    <parent link="base_link"/>
    <child link="right_caster_link"/>
    <axis xyz="0 1 0"/>
  </joint>
  <link name="right_caster_link">
    <visual>
      <origin rpy="1.5707963 0 0" xyz="0 0 0"/>
      <geometry>
        <cylinder length="0.11" radius="0.35"/>
      </geometry>
      <material name="black"/>
    </visual>
  </link>
</robot>

